<?xml version="1.0" encoding="utf-8"?>
<robot name="pde4430_cw2_robot_new"> 

  <link name="chassy">
    <inertial>
      <origin xyz="0.16333823019965 -0.363188727032132 0.142594031097362" rpy="0 0 0" />
      <mass value="6.57018555863407"/>
      <inertia
        ixx="0.0648390550758513"
        ixy="-1.65844978042012E-10"
        ixz="0.00497709736164988"
        iyy="0.0928142242078364"
        iyz="-3.59005134422651E-11"
        izz="0.14862887093943" />
    </inertial>
    <visual>
      <origin xyz="0 0 0" rpy="0 0 0" />
      <geometry>
        <mesh filename="package://pde4430_cw2_robot_description/meshes/chassy.STL" />
      </geometry>
      <material name="blue_chassy">
        <color rgba="0 0 1 1" />
      </material>
    </visual>
    <collision>
      <origin xyz="0 0 0" rpy="0 0 0" />
      <geometry>
        <mesh filename="package://pde4430_cw2_robot_description/meshes/chassy.STL" />
      </geometry>
    </collision>
  </link>

  <link name="left_wheel">
    <inertial>
      <origin xyz="-5.21804821573824E-15 0.0295390266328485 -2.47024622979097E-15" rpy="0 0 0" />
      <mass value="2.16602182282338" />
      <inertia
        ixx="0.00224997851896062"
        ixy="1.51700484940178E-16"
        ixz="5.42101086242752E-20"
        iyy="0.00381517296203438"
        iyz="7.32725756481515E-17"
        izz="0.00224997851896062" />
    </inertial>
    <visual>
      <origin xyz="0 0 0" rpy="0 0 0" />
      <geometry>
        <mesh filename="package://pde4430_cw2_robot_description/meshes/left_wheel.STL" />
      </geometry>
      <material name="black_left_wheel">
        <color rgba="0 0 0 1" />
      </material>
    </visual>
    <collision>
      <origin xyz="0 0 0" rpy="0 0 0" />
      <geometry>
        <mesh filename="package://pde4430_cw2_robot_description/meshes/left_wheel.STL" />
      </geometry>
    </collision>
  </link>

  <joint name="left_wheel_joint" type="continuous">
    <origin xyz="0.149280792728888 -0.533188727209813 0.142605370600387" rpy="3.14159265358979 -0.327303974077709 0" />
    <parent link="chassy" />
    <child link="left_wheel" />
    <axis xyz="0 1 0" />
  </joint>

  <link name="right_wheel">
    <inertial>
      <origin xyz="-5.02375918642883E-15 -0.0304609733671515 -2.45636844198316E-15" rpy="0 0 0" />
      <mass value="2.16602182282338" />
      <inertia
        ixx="0.00224997851896063"
        ixy="1.51624800598667E-16"
        ixz="3.79470760369927E-19"
        iyy="0.0038151729620344"
        iyz="7.32703087704615E-17"
        izz="0.00224997851896063" />
    </inertial>
    <visual>
      <origin xyz="0 0 0" rpy="0 0 0" />
      <geometry>
        <mesh filename="package://pde4430_cw2_robot_description/meshes/right_wheel.STL" />
      </geometry>
      <material name="black_right_wheel">
        <color rgba="0 0 0 1" />
      </material>
    </visual>
    <collision>
      <origin xyz="0 0 0" rpy="0 0 0" />
      <geometry>
        <mesh filename="package://pde4430_cw2_robot_description/meshes/right_wheel.STL" />
      </geometry>
    </collision>
  </link>

  <joint name="right_wheel_joint" type="continuous">
    <origin xyz="0.149280792728888 -0.133188727209813 0.142605370600387" rpy="-3.14159265358979 0.393094810426521 -3.14159265358979" />
    <parent link="chassy" />
    <child link="right_wheel" />
    <axis xyz="0 -1 0" />
  </joint>
  
  <link name="right_gripper">
    <inertial>
      <origin xyz="-0.116159368597421 0.15387551741621 -0.0694598084327985" rpy="0 0 0" />
      <mass value="0.15" />
      <inertia
        ixx="0.00173"
        ixy="-0.000945510032094421"
        ixz="0.00189087832371278"
        iyy="0.0268595354624139"
        iyz="0.000159653946953313"
        izz="0.0394264320820596" />
    </inertial>
    <visual>
      <origin xyz="0 0 0" rpy="0 0 0" />
      <geometry>
        <mesh filename="package://pde4430_cw2_robot_description/meshes/right_gripper.STL" />
      </geometry>
      <material name="colored_right_gripper">
        <color rgba="0.678 0.847 0.902 1" />
      </material> 
    </visual>
    <collision>
      <origin xyz="0 0 0" rpy="0 0 0" />
      <geometry>
        <mesh filename="package://pde4430_cw2_robot_description/meshes/right_gripper.STL" />
      </geometry>
      <surface>
        <friction>
          <ode mu="1.0" mu2="1.0" />
        </friction>
        <restitution>
          <ode restitution_coefficient="0.2" threshold="0.5" />
        </restitution>
      </surface>
    </collision>
  </link>

  <joint name="right_gripper_joint" type="revolute">
    <origin xyz="-0.021917 -0.32319 0.062605" rpy="1.5708 0 0.07063" />
    <parent link="chassy" />
    <child link="right_gripper" />
    <axis xyz="0 1 0" />
    <dynamics damping="0.01"/>
    <limit lower="-0.78" upper="0.61" effort="20" velocity="1" />
  </joint>

  <link name="left_gripper">
    <inertial>
      <origin xyz="-0.129875210051789 0.153218916331966 0.0723549039504964" rpy="0 0 0" />
      <mass value="0.15" />
      <inertia
        ixx="0.00173"
        ixy="-0.000945510032094421"
        ixz="0.00189087832371278"
        iyy="0.0268595354624139"
        iyz="0.000159653946953313"
        izz="0.0394264320820596" />
    </inertial>
    <visual>
      <origin xyz="0 0 0" rpy="0 0 0" />
      <geometry>
        <mesh filename="package://pde4430_cw2_robot_description/meshes/left_gripper.STL" />
      </geometry>
      <material name="colored_left_gripper">
        <color rgba="0.678 0.847 0.902 1" />
      </material>
    </visual>
    <collision>
      <origin xyz="0 0 0" rpy="0 0 0" />
      <geometry>
        <mesh filename="package://pde4430_cw2_robot_description/meshes/left_gripper.STL" />
      </geometry>
    <!-- </collision>
    <collision> -->
      <surface>
        <friction>
          <ode mu="1.0" mu2="1.0" />
        </friction>
        <restitution>
          <ode restitution_coefficient="0.2" threshold="0.5" />
        </restitution>
      </surface>
    </collision>
  </link>

  <joint name="left_gripper_joint" type="revolute">
    <origin xyz="-0.021917 -0.40319 0.062605" rpy="1.5708 0 -0.081634" />
    <parent link="chassy" />
    <child link="left_gripper" />
    <axis xyz="0 1 0" />
    <dynamics damping="0.01"/>
    <limit lower="-0.78" upper="0.61" effort="20" velocity="1" />
    <mimic joint="right_gripper_joint" multiplier="-1" offset="0" />
  </joint>

  <!-- Simulated lidar sensor link -->
  <link name="lidar_link">
    <inertial>
      <origin xyz="-0.00683937823834196 0.0964816118260995 0.00829015544041439" rpy="0 0 0" />
      <mass value="1.0" />
      <inertia ixx="0.001" iyy="0.001" izz="0.001" ixy="0" ixz="0" iyz="0"/>
    </inertial>
    <visual name="lidar_sensor_visual">
      <origin xyz="0 0 0" rpy="0 0 0" />
      <geometry>
        <mesh filename="package://pde4430_cw2_robot_description/meshes/lidar.STL" />
      </geometry>
      <material name="lidar_blue">
        <color rgba="0 0 1 1" />
      </material>
    </visual>
    <collision>
      <origin xyz="0 0 0" rpy="0 0 0" />
      <geometry>
        <mesh filename="package://pde4430_cw2_robot_description/meshes/lidar.STL" />
      </geometry>
    </collision>
  </link>

  <!-- Simulate lidar sensor (Gazebo or ROS) -->
  <joint name="lidar_joint" type="fixed">
    <origin xyz="0.19007 -0.35181 0.16761" rpy="1.5708 0 0" />
    <parent link="chassy" />
    <child link="lidar_link" />
    <axis xyz="0 0 0" />
  </joint>

  <transmission name="left_wheel_trans">
    <type>transmission_interface/SimpleTransmission</type>
    <joint name="left_wheel_joint">
      <hardwareInterface>hardware_interface/VelocityJointInterface</hardwareInterface>
    </joint>
    <actuator name="left_wheel_motor">
      <hardwareInterface>hardware_interface/VelocityJointInterface</hardwareInterface>
    </actuator>
  </transmission>

  <transmission name="right_wheel_trans">
    <type>transmission_interface/SimpleTransmission</type>
    <joint name="right_wheel_joint">
      <hardwareInterface>hardware_interface/VelocityJointInterface</hardwareInterface>
    </joint>
    <actuator name="right_wheel_motor">
      <hardwareInterface>hardware_interface/VelocityJointInterface</hardwareInterface>
    </actuator>
  </transmission>

  <transmission name="left_gripper_trans">
    <type>transmission_interface/SimpleTransmission</type>
    <joint name="left_gripper_joint">
      <hardwareInterface>hardware_interface/PositionJointInterface</hardwareInterface> 
    </joint>
    <actuator name="left_gripper_motor">
      <hardwareInterface>hardware_interface/PositionJointInterface</hardwareInterface> 
    </actuator>
  </transmission>

  <transmission name="right_gripper_trans">
    <type>transmission_interface/SimpleTransmission</type>
    <joint name="right_gripper_joint">
      <hardwareInterface>hardware_interface/PositionJointInterface</hardwareInterface> 
    </joint>
    <actuator name="right_gripper_motor">
      <hardwareInterface>hardware_interface/PositionJointInterface</hardwareInterface> 
    </actuator>
  </transmission>

  <!-- Below plugin for wheels and gripper -->
  <gazebo>
    <plugin name="gazebo_ros_control" filename="libgazebo_ros_control.so">
      <robotNamespace>/</robotNamespace>
    </plugin>
  </gazebo>
  
  <gazebo reference="lidar_link">
    <sensor type="ray" name="rplidar">
      <pose>0 0 -0.2 0 0 0</pose>
      <visualize>false</visualize>
      <update_rate>10</update_rate>
      <ray>
        <scan>
          <horizontal>
            <samples>360</samples>
            <resolution>1</resolution>
            <min_angle>-3.14159</min_angle>
            <max_angle>3.14159</max_angle>
          </horizontal>
        </scan>
        <range>
          <min>0.1</min>
          <max>6.0</max>
          <resolution>0.01</resolution>
        </range>
      </ray>
      <plugin name="gazebo_ros_rplidar_controller" filename="libgazebo_ros_laser.so">
        <ros>
          <frame_id>/scan</frame_id>
          <param name="scan_topic" value="/scan"/>
          <remapping>~/out:=scan</remapping>
        </ros>
        <output_type>sensor_msgs/LaserScan</output_type>
        <frame_name>laser_link</frame_name>
      </plugin>
    </sensor> 
  </gazebo>
    
</robot>
